<?xml version="1.0"?>
<robot name="reto_robot">
    
    <!-- Base -->
    <link name="base_link">
        <visual>
            <geometry>
                <box size="0.5 0.5 0.2"/>
            </geometry>
            <material name="blue">
                <color rgba="0 0 1 1"/>
            </material>
        </visual>
    </link>
    
    <!-- Eslabón 0-->
    <link name="arm_link_0">
        <visual>
            <geometry>
                <cylinder radius="0.05" length="0.5"/>
            </geometry>
            <material name="red">
                <color rgba="1 0 0 1"/>
            </material>
        </visual>
    </link>
    
    <!-- Eslabón 1-->
    <link name="arm_link_1">
        <visual>
            <geometry>
                <cylinder radius="0.05" length="0.5"/>
            </geometry>
            <material name="red">
                <color rgba="1 0 0 1"/>
            </material>
        </visual>
    </link>

    <!-- Eslabón 2 -->
    <link name="arm_link_2">
        <visual>
            <geometry>
                <cylinder radius="0.05" length="0.5"/>
            </geometry>
            <material name="red">
                <color rgba="1 0 0 1"/>
            </material>
        </visual>
    </link>

    <!-- Junta de Revolución 1-->
    <joint name="joint1" type="revolute">
        <parent link="base_link"/>
        <child link="arm_link_0"/>
        <origin xyz="0 0 0.1" rpy="0 0 0"/>
        <axis xyz="0 0 1"/>
        <limit effort="10.0" lower="-1.57" upper="1.57" velocity="1.0"/>
    </joint>
    
    <!-- Junta de Revolución 2-->
    <joint name="joint2" type="revolute">
        <parent link="arm_link_0"/>
        <child link="arm_link_1"/>
        <origin xyz="0 0 0.25" rpy="0 0 0"/>
        <axis xyz="1 0 0"/>
        <limit effort="10.0" lower="-1.57" upper="1.57" velocity="1.0"/>
    </joint>
    
    <!-- Junta de Revolución 3 -->
    <joint name="joint3" type="revolute">
        <parent link="arm_link_1"/>
        <child link="arm_link_2"/>
        <origin xyz="0 0 0.25" rpy="0 0 0"/>
        <axis xyz="0 1 0"/>
        <limit effort="10.0" lower="-1.57" upper="1.57" velocity="1.0"/>
    </joint>
</robot>
